<?xml version="1.0" encoding="UTF-8"?>
<!-- Generated by org.testng.reporters.JUnitXMLReporter -->
<testsuite hostname="HFJS-20190508QA" name="Test" tests="4" failures="2" timestamp="8 Jan 2020 09:02:16 GMT" time="0.101" errors="0">
  <testcase name="test1" time="0.025" classname="org.TestDemo.AssertDemo">
    <failure type="java.lang.AssertionError" message="expected [2] but found [1]">
      <![CDATA[java.lang.AssertionError: expected [2] but found [1]
	at org.TestDemo.AssertDemo.test1(AssertDemo.java:10)
... Removed 30 stack frames]]>
    </failure>
  </testcase> <!-- test1 -->
  <testcase name="test2" time="0.002" classname="org.TestDemo.AssertDemo"/>
  <testcase name="test3" time="0.001" classname="org.TestDemo.AssertDemo"/>
  <testcase name="logDemo" time="0.002" classname="org.TestDemo.AssertDemo">
    <failure type="java.lang.RuntimeException" message="这是我自己抛的异常">
      <![CDATA[java.lang.RuntimeException: 这是我自己抛的异常
	at org.TestDemo.AssertDemo.logDemo(AssertDemo.java:27)
... Removed 24 stack frames]]>
    </failure>
  </testcase> <!-- logDemo -->
</testsuite> <!-- Test -->
